Workbook

Sheet hukuman wise
A1: Pembajakan adalah tindakan 1ng wajar karena membantu mas1rakat 1ng 2 mampu mendapatkan Software | B1: Sa1 takut akan dijerat hukum jika menggunakan software bajakan | C1: Sa1 akan berhenti menggunakan software bajakan jika Hukum melarangn1 | D1: summary | E1: Sa1 pernah/sedang menggunakan software bajakan
A2: 5 | B2: 1 | C2: 1 | D2: =SUM(B2:C2) -> 2 | E2: 1
A3: 2 | B3: 1 | C3: 1 | D3: =SUM(B3:C3) -> 2 | E3: 1
A4: 1 | B4: 2 | C4: 1 | D4: =SUM(B4:C4) -> 3 | E4: 1 | F4: SUMMARY OUTPUT
A5: 4 | B5: 1 | C5: 1 | D5: =SUM(B5:C5) -> 2 | E5: 1
A6: 3 | B6: 1 | C6: 1 | D6: =SUM(B6:C6) -> 2 | E6: 1 | F6: Regression Statistics
A7: 2 | B7: 1 | C7: 1 | D7: =SUM(B7:C7) -> 2 | E7: 1 | F7: Multiple R | G7: 0.080197718
A8: 4 | B8: 2 | C8: 2 | D8: =SUM(B8:C8) -> 4 | E8: 1 | F8: R Square | G8: 0.0064316739
A9: 2 | B9: 1 | C9: 2 | D9: =SUM(B9:C9) -> 3 | E9: 1 | F9: Adjusted R Square | G9: -0.012314898
A10: 2 | B10: 1 | C10: 2 | D10: =SUM(B10:C10) -> 3 | E10: 2 | F10: Standard Error | G10: 0.73986479
A11: 3 | B11: 1 | C11: 2 | D11: =SUM(B11:C11) -> 3 | E11: 2 | F11: Observations | G11: 55
A12: 1 | B12: 1 | C12: 1 | D12: =SUM(B12:C12) -> 2 | E12: 2
A13: 2 | B13: 1 | C13: 1 | D13: =SUM(B13:C13) -> 2 | E13: 1 | F13: ANOVA
A14: 3 | B14: 2 | C14: 1 | D14: =SUM(B14:C14) -> 3 | E14: 2 | G14: df | H14: SS | I14: MS | J14: F | K14: Significance F
A15: 2 | B15: 1 | C15: 1 | D15: =SUM(B15:C15) -> 2 | E15: 1 | F15: Regression | G15: 1 | H15: 0.18780488 | I15: 0.18780488 | J15: 0.34308533 | K15: 0.56053976
A16: 3 | B16: 2 | C16: 1 | D16: =SUM(B16:C16) -> 3 | E16: 1 | F16: Residual | G16: 53 | H16: 29.012195 | I16: 0.54739991
A17: 2 | B17: 1 | C17: 1 | D17: =SUM(B17:C17) -> 2 | E17: 2 | F17: Total | G17: 54 | H17: 29.2
A18: 2 | B18: 2 | C18: 2 | D18: =SUM(B18:C18) -> 4 | E18: 1
A19: 3 | B19: 1 | C19: 1 | D19: =SUM(B19:C19) -> 2 | E19: 1 | G19: Coefficients | H19: Standard Error | I19: t Stat | J19: P-value | K19: Lower 95% | L19: Upper 95% | M19: Lower 95,0% | N19: Upper 95,0%
A20: 3 | B20: 1 | C20: 1 | D20: =SUM(B20:C20) -> 2 | E20: 1 | F20: Intercept | G20: 2.7682927 | H20: 0.30414612 | I20: 9.101851 | J20: 2.0323109e-12 | K20: 2.1582528 | L20: 3.3783325 | M20: 2.1582528 | N20: 3.3783325
A21: 2 | B21: 1 | C21: 1 | D21: =SUM(B21:C21) -> 2 | E21: 2 | F21: Dependent | G21: -0.13414634 | H21: 0.22902229 | I21: -0.58573486 | J21: 0.56053976 | K21: -0.59350689 | L21: 0.32521421 | M21: -0.59350689 | N21: 0.32521421
A22: 4 | B22: 1 | C22: 2 | D22: =SUM(B22:C22) -> 3 | E22: 1
A23: 2 | B23: 1 | C23: 1 | D23: =SUM(B23:C23) -> 2 | E23: 2
A24: 3 | B24: 1 | C24: 1 | D24: =SUM(B24:C24) -> 2 | E24: 1 | I24: Z
A25: 4 | B25: 2 | C25: 2 | D25: =SUM(B25:C25) -> 4 | E25: 1
A26: 2 | B26: 2 | C26: 1 | D26: =SUM(B26:C26) -> 3 | E26: 1
A27: 3 | B27: 1 | C27: 1 | D27: =SUM(B27:C27) -> 2 | E27: 1
A28: 4 | B28: 2 | C28: 2 | D28: =SUM(B28:C28) -> 4 | E28: 1
A29: 2 | B29: 1 | C29: 2 | D29: =SUM(B29:C29) -> 3 | E29: 1
A30: 5 | B30: 1 | C30: 1 | D30: =SUM(B30:C30) -> 2 | E30: 1
A31: 3 | B31: 2 | C31: 2 | D31: =SUM(B31:C31) -> 4 | E31: 2
A32: 3 | B32: 2 | C32: 2 | D32: =SUM(B32:C32) -> 4 | E32: 1
A33: 1 | B33: 1 | C33: 1 | D33: =SUM(B33:C33) -> 2 | E33: 2
A34: 1 | B34: 1 | C34: 1 | D34: =SUM(B34:C34) -> 2 | E34: 2
A35: 2 | B35: 1 | C35: 2 | D35: =SUM(B35:C35) -> 3 | E35: 1
A36: 4 | B36: 1 | C36: 2 | D36: =SUM(B36:C36) -> 3 | E36: 2
... A56: 2 | B56: 1 | C56: 1 | D56: =SUM(B56:C56) -> 2 | E56: 1

Sheet tau hukum
A1: Saya tahu dan paham tentang hukum hak cipta | B1: Sa1 pernah/sedang menggunakan software bajakan
A2: 5 | B2: 1
A3: 4 | B3: 1 | D3: SUMMARY OUTPUT
A4: 2 | B4: 1
A5: 4 | B5: 1 | D5: Regression Statistics
A6: 3 | B6: 1 | D6: Multiple R | E6: 0.040828302
A7: 5 | B7: 1 | D7: R Square | E7: 0.0016669502
A8: 4 | B8: 1 | D8: Adjusted R Square | E8: -0.017169522
A9: 4 | B9: 1 | D9: Standard Error | E9: 0.9837948
A10: 5 | B10: 2 | D10: Observations | E10: 55
A11: 5 | B11: 2
A12: 4 | B12: 2 | D12: ANOVA
A13: 4 | B13: 1 | E13: df | F13: SS | G13: MS | H13: F | I13: Significance F
A14: 3 | B14: 2 | D14: Regression | E14: 1 | F14: 0.085650934 | G14: 0.085650934 | H14: 0.088495881 | I14: 0.76726105
A15: 3 | B15: 1 | D15: Residual | E15: 53 | F15: 51.296167 | G15: 0.96785221
A16: 3 | B16: 1 | D16: Total | E16: 54 | F16: 51.381818
A17: 3 | B17: 2
A18: 4 | B18: 1 | E18: Coefficients | F18: Standard Error | G18: t Stat | H18: P-value | I18: Lower 95% | J18: Upper 95% | K18: Lower 95,0% | L18: Upper 95,0%
A19: 3 | B19: 1 | D19: Intercept | E19: 3.8954704 | F19: 0.40442169 | G19: 9.6321994 | H19: 3.0679313e-13 | I19: 3.0843032 | J19: 4.7066376 | K19: 3.0843032 | L19: 4.7066376
A20: 4 | B20: 1 | D20: Dependent | E20: -0.090592334 | F20: 0.30452989 | G20: -0.29748257 | H20: 0.76726105 | I20: -0.70140194 | J20: 0.52021727 | K20: -0.70140194 | L20: 0.52021727
A21: 5 | B21: 2
A22: 3 | B22: 1
A23: 3 | B23: 2
A24: 4 | B24: 1
A25: 3 | B25: 1
A26: 5 | B26: 1
A27: 5 | B27: 1
A28: 4 | B28: 1
A29: 3 | B29: 1
A30: 3 | B30: 1
A31: 4 | B31: 2
A32: 4 | B32: 1
... A56: 4 | B56: 1

Sheet sikap banyak independen
A1: Pembajakan adalah tindakan 1ng wajar karena membantu mas1rakat 1ng 2 mampu mendapatkan Software | B1: Pembajakan software 2 boleh dilakukan, sekalipun bia1n1 mahal dan sa1 2 mampu membeli lisensin1 | C1: Menurut sa1 pembajakan software dapat merugikan perusahaan | D1: Sa1 merasa malu dan bersalah ketika menggunakan software bajakan | E1: Column1 | F1: Sa1 pernah/sedang menggunakan software bajakan
A2: 1 | B2: 5 | C2: 5 | D2: 5 | E2: =SUM(A2:D2) -> 16 | F2: 1
A3: 4 | B3: 2 | C3: 4 | D3: 4 | E3: =SUM(A3:D3) -> 14 | F3: 1
A4: 5 | B4: 3 | C4: 5 | D4: 3 | E4: =SUM(A4:D4) -> 16 | F4: 1
A5: 2 | B5: 4 | C5: 5 | D5: 3 | E5: =SUM(A5:D5) -> 14 | F5: 1
A6: 3 | B6: 2 | C6: 4 | D6: 4 | E6: =SUM(A6:D6) -> 13 | F6: 1
A7: 4 | B7: 4 | C7: 5 | D7: 4 | E7: =SUM(A7:D7) -> 17 | F7: 1 | K7: 1 | L7: 5
A8: 2 | B8: 2 | C8: 2 | D8: 1 | E8: =SUM(A8:D8) -> 7 | F8: 1 | J8: 1 | K8: 1
A9: 4 | B9: 4 | C9: 5 | D9: 4 | E9: =SUM(A9:D9) -> 17 | F9: 1 | J9: 5 | K9: 0.50722541 | L9: 1
A10: 4 | B10: 4 | C10: 5 | D10: 4 | E10: =SUM(A10:D10) -> 17 | F10: 1
A11: 4 | B11: 1 | C11: 5 | D11: 5 | E11: =SUM(A11:D11) -> 15 | F11: 1
A12: 3 | B12: 2 | C12: 4 | D12: 2 | E12: =SUM(A12:D12) -> 11 | F12: 1 | J12: =CORREL(E2:E56,F2:F56) -> 0.25523265
A13: 4 | B13: 4 | C13: 5 | D13: 2 | E13: =SUM(A13:D13) -> 15 | F13: 1
A14: 3 | B14: 3 | C14: 3 | D14: 3 | E14: =SUM(A14:D14) -> 12 | F14: 1
A15: 3 | B15: 5 | C15: 5 | D15: 4 | E15: =SUM(A15:D15) -> 17 | F15: 1
A16: 2 | B16: 3 | C16: 4 | D16: 3 | E16: =SUM(A16:D16) -> 12 | F16: 1
A17: 3 | B17: 5 | C17: 4 | D17: 5 | E17: =SUM(A17:D17) -> 17 | F17: 1
A18: 2 | B18: 3 | C18: 5 | D18: 1 | E18: =SUM(A18:D18) -> 11 | F18: 1
A19: 4 | B19: 4 | C19: 5 | D19: 5 | E19: =SUM(A19:D19) -> 18 | F19: 1
A20: 3 | B20: 4 | C20: 5 | D20: 5 | E20: =SUM(A20:D20) -> 17 | F20: 1
A21: 2 | B21: 2 | C21: 3 | D21: 1 | E21: =SUM(A21:D21) -> 8 | F21: 1
A22: 4 | B22: 5 | C22: 5 | D22: 4 | E22: =SUM(A22:D22) -> 18 | F22: 1
A23: 1 | B23: 2 | C23: 5 | D23: 2 | E23: =SUM(A23:D23) -> 10 | F23: 1
A24: 3 | B24: 5 | C24: 5 | D24: 2 | E24: =SUM(A24:D24) -> 15 | F24: 1
... A56: 3 | B56: 3 | C56: 4 | D56: 5 | E56: =SUM(A56:D56) -> 15 | F56: 2

Sheet Raw data numerical
A1: Umur | B1: Gender | C1: Penghasilan/ Uang saku perbulan | D1: Sa1 memiliki akses pemba1ran international untuk pembelian lisensi software (paypall, credit card) | E1: Sa1 memiliki komputer/laptop pribadi | F1: Sa1 sudah menggunakan komputer/laptop pribadi sejak | G1: Pembajakan adalah tindakan 1ng wajar karena membantu mas1rakat 1ng 2 mampu mendapatkan Software | H1: Pembajakan software 2 boleh dilakukan, sekalipun bia1n1 mahal dan sa1 2 mampu membeli lisensin1 | I1: Menurut sa1 pembajakan software dapat merugikan perusahaan | J1: Sa1 merasa malu dan bersalah ketika menggunakan software bajakan | K1: Sa1 tahu dan paham tentang hukum hak cipta | L1: Sa1 takut akan dijerat hukum jika menggunakan software bajakan | M1: Sa1 akan berhenti menggunakan software bajakan jika Hukum melarangn1 | N1: Sa1 pernah/sedang menggunakan software bajakan
A2: 21 | B2: 1 | C2: 1 | D2: 2 | E2: 1 | F2: 3 | G2: 5 | H2: 5 | I2: 5 | J2: 5 | K2: 5 | L2: 1 | M2: 1 | N2: 1
A3: 18 | B3: 2 | C3: 1 | D3: 2 | E3: 1 | F3: 2 | G3: 2 | H3: 2 | I3: 4 | J3: 4 | K3: 4 | L3: 1 | M3: 1 | N3: 1
A4: 17 | B4: 1 | C4: 2 | D4: 2 | E4: 1 | F4: 2 | G4: 1 | H4: 3 | I4: 5 | J4: 3 | K4: 2 | L4: 2 | M4: 1 | N4: 1
A5: 18 | B5: 1 | C5: 1 | D5: 1 | E5: 1 | F5: 2 | G5: 4 | H5: 4 | I5: 5 | J5: 3 | K5: 4 | L5: 1 | M5: 1 | N5: 1 | Q5: Umur | R5: Gender | S5: Penghasilan/ Uang saku perbulan | T5: Sa1 memiliki akses pemba1ran international untuk pembelian lisensi software (paypall, credit card) | U5: Sa1 memiliki komputer/laptop pribadi | V5: Sa1 sudah menggunakan komputer/laptop pribadi sejak | W5: Pembajakan adalah tindakan 1ng wajar karena membantu mas1rakat 1ng 2 mampu mendapatkan Software | X5: Pembajakan software 2 boleh dilakukan, sekalipun bia1n1 mahal dan sa1 2 mampu membeli lisensin1 | Y5: Menurut sa1 pembajakan software dapat merugikan perusahaan | Z5: Sa1 merasa malu dan bersalah ketika menggunakan software bajakan | AA5: Sa1 tahu dan paham tentang hukum hak cipta | AB5: Sa1 takut akan dijerat hukum jika menggunakan software bajakan | AC5: Sa1 akan berhenti menggunakan software bajakan jika Hukum melarangn1 | AD5: Sa1 pernah/sedang menggunakan software bajakan
A6: 18 | B6: 1 | C6: 1 | D6: 2 | E6: 1 | F6: 3 | G6: 3 | H6: 2 | I6: 4 | J6: 4 | K6: 3 | L6: 1 | M6: 1 | N6: 1 | P6: Umur | Q6: =VARP('Raw data numerical'!$A$2:$A$56) -> 0.90247934
A7: 18 | B7: 2 | C7: 1 | D7: 2 | E7: 1 | F7: 3 | G7: 2 | H7: 4 | I7: 5 | J7: 4 | K7: 5 | L7: 1 | M7: 1 | N7: 1 | P7: Gender | Q7: -0.0099173554 | R7: =VARP('Raw data numerical'!$B$2:$B$56) -> 0.24330579
A8: 20 | B8: 1 | C8: 2 | D8: 2 | E8: 1 | F8: 3 | G8: 4 | H8: 2 | I8: 2 | J8: 1 | K8: 4 | L8: 2 | M8: 2 | N8: 1 | P8: Penghasilan/ Uang saku perbulan | Q8: 0.084297521 | R8: 0.037355372 | S8: =VARP('Raw data numerical'!$C$2:$C$56) -> 0.29884298
A9: 18 | B9: 2 | C9: 1 | D9: 2 | E9: 1 | F9: 3 | G9: 2 | H9: 4 | I9: 5 | J9: 4 | K9: 4 | L9: 1 | M9: 2 | N9: 1 | P9: Sa1 memiliki akses pemba1ran international untuk pembelian lisensi software (paypall, credit card) | Q9: 0.051239669 | R9: 0.0095867769 | S9: -0.014214876 | T9: =VARP('Raw data numerical'!$D$2:$D$56) -> 0.22016529
A10: 18 | B10: 2 | C10: 1 | D10: 2 | E10: 1 | F10: 3 | G10: 2 | H10: 4 | I10: 5 | J10: 5 | K10: 5 | L10: 1 | M10: 2 | N10: 2 | P10: Sa1 memiliki komputer/laptop pribadi | Q10: 0 | R10: 0 | S10: 0 | T10: 0 | U10: =VARP('Raw data numerical'!$E$2:$E$56) -> 0
A11: 19 | B11: 1 | C11: 1 | D11: 2 | E11: 1 | F11: 3 | G11: 3 | H11: 3 | I11: 5 | J11: 4 | K11: 5 | L11: 1 | M11: 2 | N11: 2 | P11: Sa1 sudah menggunakan komputer/laptop pribadi sejak | Q11: 0.01322314 | R11: -0.012892562 | S11: 0.04231405 | T11: 0.021157025 | U11: 0 | V11: =VARP('Raw data numerical'!$F$2:$F$56) -> 0.3953719
A12: 18 | B12: 2 | C12: 2 | D12: 1 | E12: 1 | F12: 3 | G12: 1 | H12: 5 | I12: 5 | J12: 4 | K12: 4 | L12: 1 | M12: 1 | N12: 2 | P12: Pembajakan adalah tindakan 1ng wajar karena membantu mas1rakat 1ng 2 mampu mendapatkan Software | Q12: 0.028099174 | R12: -0.1814876 | S12: -0.088264463 | T12: -0.035041322 | U12: 0 | V12: 0.038347107 | W12: x
A13: 17 | B13: 1 | C13: 2 | D13: 1 | E13: 1 | F13: 3 | G13: 2 | H13: 4 | I13: 5 | J13: 4 | K13: 4 | L13: 1 | M13: 1 | N13: 1 | P13: Pembajakan software 2 boleh dilakukan, sekalipun bia1n1 mahal dan sa1 2 mampu membeli lisensin1 | Q13: 0.021487603 | R13: 0.1431405 | S13: 0.01785124 | T13: -0.063801653 | U13: 0 | V13: -0.013884298 | W13: -0.66677686 | X13: =VARP('Raw data numerical'!$H$2:$H$56) -> 1.4128926
A14: 19 | B14: 2 | C14: 1 | D14: 2 | E14: 1 | F14: 3 | G14: 3 | H14: 4 | I14: 4 | J14: 4 | K14: 3 | L14: 2 | M14: 1 | N14: 2 | P14: Menurut sa1 pembajakan software dapat merugikan perusahaan | Q14: -0.052892562 | R14: 0.084297521 | S14: 0.019834711 | T14: 0.046280992 | U14: 0 | V14: -0.021487603 | W14: -0.39338843 | X14: 0.55371901 | Y14: =VARP('Raw data numerical'!$I$2:$I$56) -> 0.81322314
A15: 19 | B15: 2 | C15: 1 | D15: 2 | E15: 1 | F15: 2 | G15: 2 | H15: 1 | I15: 5 | J15: 5 | K15: 3 | L15: 1 | M15: 1 | N15: 1 | P15: Sa1 merasa malu dan bersalah ketika menggunakan software bajakan | Q15: -0.20165289 | R15: 0.27206612 | S15: -0.059834711 | T15: 0.051900826 | U15: 0 | V15: -0.02214876 | W15: -0.8138843 | X15: 0.9153719 | Y15: 0.51404959 | Z15: =VARP('Raw data numerical'!$J$2:$J$56) -> 1.8459504
A16: 18 | B16: 1 | C16: 2 | D16: 2 | E16: 1 | F16: 3 | G16: 3 | H16: 2 | I16: 4 | J16: 2 | K16: 3 | L16: 2 | M16: 1 | N16: 1 | P16: Sa1 tahu dan paham tentang hukum hak cipta | Q16: 0.06446281 | R16: 0.036694215 | S16: -0.033719008 | T16: -0.016859504 | U16: 0 | V16: 0.1292562 | W16: -0.047603306 | X16: 0.51504132 | Y16: 0.20661157 | Z16: 0.60429752 | AA16: =VARP('Raw data numerical'!$K$2:$K$56) -> 0.93421488
A17: 17 | B17: 2 | C17: 1 | D17: 2 | E17: 1 | F17: 2 | G17: 2 | H17: 4 | I17: 5 | J17: 5 | K17: 3 | L17: 1 | M17: 1 | N17: 2 | P17: Sa1 takut akan dijerat hukum jika menggunakan software bajakan | Q17: 0.051239669 | R17: -0.041322314 | S17: 0.033057851 | T17: -0.0016528926 | U17: 0 | V17: 0.0066115702 | W17: 0.11404959 | X17: -0.18016529 | Y17: -0.062809917 | Z17: -0.30082645 | AA17: -0.067768595 | AB17: =VARP('Raw data numerical'!$L$2:$L$56) -> 0.19834711
A18: 19 | B18: 1 | C18: 2 | D18: 2 | E18: 1 | F18: 3 | G18: 2 | H18: 4 | I18: 5 | J18: 2 | K18: 4 | L18: 2 | M18: 2 | N18: 1 | P18: Sa1 akan berhenti menggunakan software bajakan jika Hukum melarangn1 | Q18: 0.039669421 | R18: -0.045950413 | S18: -0.02214876 | T18: -0.0019834711 | U18: 0 | V18: 0.015206612 | W18: 0.14413223 | X18: -0.099834711 | Y18: -0.10082645 | Z18: -0.25190083 | AA18: -0.03768595 | AB18: 0.056198347 | AC18: =VARP('Raw data numerical'!$M$2:$M$56) -> 0.22016529
A19: 17 | B19: 1 | C19: 1 | D19: 1 | E19: 1 | F19: 3 | G19: 3 | H19: 3 | I19: 3 | J19: 3 | K19: 3 | L19: 1 | M19: 1 | N19: 1 | P19: Sa1 pernah/sedang menggunakan software bajakan | Q19: -0.047933884 | R19: 0.057190083 | S19: -0.069752066 | T19: -0.0076033058 | U19: 0 | V19: -0.020495868 | W19: -0.12628099 | X19: 0.10214876 | Y19: -0.0016528926 | Z19: 0.17983471 | AA19: -0.017190083 | AB19: -0.033057851 | AC19: 0.0076033058 | AD19: =VARP('Raw data numerical'!$N$2:$N$56) -> 0.18975207
A20: 19 | B20: 1 | C20: 1 | D20: 2 | E20: 1 | F20: 3 | G20: 3 | H20: 5 | I20: 5 | J20: 4 | K20: 4 | L20: 1 | M20: 1 | N20: 1
A21: 18 | B21: 1 | C21: 1 | D21: 2 | E21: 1 | F21: 1 | G21: 2 | H21: 5 | I21: 5 | J21: 5 | K21: 5 | L21: 1 | M21: 1 | N21: 2
A22: 18 | B22: 1 | C22: 2 | D22: 1 | E22: 1 | F22: 3 | G22: 4 | H22: 3 | I22: 4 | J22: 3 | K22: 3 | L22: 1 | M22: 2 | N22: 1
A23: 19 | B23: 2 | C23: 1 | D23: 2 | E23: 1 | F23: 2 | G23: 2 | H23: 3 | I23: 3 | J23: 3 | K23: 3 | L23: 1 | M23: 1 | N23: 2
A24: 17 | B24: 2 | C24: 1 | D24: 2 | E24: 1 | F24: 3 | G24: 3 | H24: 5 | I24: 4 | J24: 5 | K24: 4 | L24: 1 | M24: 1 | N24: 1
A25: 18 | B25: 1 | C25: 1 | D25: 1 | E25: 1 | F25: 2 | G25: 4 | H25: 3 | I25: 5 | J25: 1 | K25: 3 | L25: 2 | M25: 2 | N25: 1
A26: 20 | B26: 1 | C26: 1 | D26: 1 | E26: 1 | F26: 2 | G26: 2 | H26: 4 | I26: 5 | J26: 5 | K26: 5 | L26: 2 | M26: 1 | N26: 1
A27: 18 | B27: 1 | C27: 1 | D27: 2 | E27: 1 | F27: 3 | G27: 3 | H27: 4 | I27: 5 | J27: 5 | K27: 5 | L27: 1 | M27: 1 | N27: 1
A28: 19 | B28: 2 | C28: 1 | D28: 2 | E28: 1 | F28: 3 | G28: 4 | H28: 2 | I28: 3 | J28: 1 | K28: 4 | L28: 2 | M28: 2 | N28: 1
A29: 19 | B29: 2 | C29: 2 | D29: 2 | E29: 1 | F29: 1 | G29: 2 | H29: 5 | I29: 5 | J29: 4 | K29: 3 | L29: 1 | M29: 2 | N29: 1
A30: 18 | B30: 1 | C30: 2 | D30: 2 | E30: 1 | F30: 2 | G30: 5 | H30: 2 | I30: 5 | J30: 2 | K30: 3 | L30: 1 | M30: 1 | N30: 1
A31: 18 | B31: 1 | C31: 1 | D31: 1 | E31: 1 | F31: 1 | G31: 3 | H31: 3 | I31: 3 | J31: 4 | K31: 4 | L31: 2 | M31: 2 | N31: 2
... A56: 21 | B56: 2 | C56: 3 | D56: 1 | E56: 1 | F56: 3 | G56: 2 | H56: 4 | I56: 4 | J56: 4 | K56: 4 | L56: 1 | M56: 1 | N56: 1
A62: Laki Laki = 1
A63: perempuan = 2
A67: Ya = 1
A68: Tidak = 2

Sheet Pengetahuan
A1: Saya sudah menggunakan komputer/laptop pribadi sejak | B1: Saya pernah/sedang menggunakan software bajakan
A2: 3 | B2: 1
A3: 2 | B3: 1
A4: 2 | B4: 1
A5: 2 | B5: 1
A6: 3 | B6: 1
A7: 3 | B7: 1
A8: 3 | B8: 1
A9: 3 | B9: 1
A10: 3 | B10: 2 | D10: SUMMARY OUTPUT
A11: 3 | B11: 2
A12: 3 | B12: 2 | D12: Regression Statistics
A13: 3 | B13: 1 | D13: Multiple R | E13: 0.074829037
A14: 3 | B14: 2 | D14: R Square | E14: 0.0055993847
A15: 2 | B15: 1 | D15: Adjusted R Square | E15: -0.013162891
A16: 3 | B16: 1 | D16: Standard Error | E16: 0.63874425
A17: 2 | B17: 2 | D17: Observations | E17: 55
A18: 3 | B18: 1
A19: 3 | B19: 1 | D19: ANOVA
A20: 3 | B20: 1 | E20: df | F20: SS | G20: MS | H20: F | I20: Significance F
A21: 1 | B21: 2 | D21: Regression | E21: 1 | F21: 0.12176117 | G21: 0.12176117 | H21: 0.29843846 | I21: 0.58715549
A22: 3 | B22: 1 | D22: Residual | E22: 53 | F22: 21.623693 | G22: 0.40799421
A23: 2 | B23: 2 | D23: Total | E23: 54 | F23: 21.745455
A24: 3 | B24: 1
A25: 2 | B25: 1 | E25: Coefficients | F25: Standard Error | G25: t Stat | H25: P-value | I25: Lower 95% | J25: Upper 95% | K25: Lower 95,0% | L25: Upper 95,0%
A26: 2 | B26: 1 | D26: Intercept | E26: 2.6445993 | F26: 0.26257715 | G26: 10.071704 | H26: 6.5497977e-14 | I26: 2.1179362 | J26: 3.1712624 | K26: 2.1179362 | L26: 3.1712624
A27: 3 | B27: 1 | D27: Saya pernah/sedang menggunakan software bajakan | E27: -0.10801394 | F27: 0.19772082 | G27: -0.54629521 | H27: 0.58715549 | I27: -0.50459168 | J27: 0.2885638 | K27: -0.50459168 | L27: 0.2885638
A28: 3 | B28: 1
A29: 1 | B29: 1
A30: 2 | B30: 1
A31: 1 | B31: 2
A32: 3 | B32: 1
A33: 3 | B33: 2
A34: 3 | B34: 2
A35: 2 | B35: 1
A36: 3 | B36: 2
A37: 1 | B37: 2
A38: 3 | B38: 1
A39: 3 | B39: 2
... A56: 3 | B56: 1

Sheet kepemilikan
A1: Saya memiliki komputer/laptop pribadi | B1: Saya pernah/sedang menggunakan software bajakan
A2: 1 | B2: 1
A3: 1 | B3: 1
A4: 1 | B4: 1
A5: 1 | B5: 1 | Q5: 1 | R5: 1
A6: 1 | B6: 1 | D6: =CORREL(A2:A56,B2:B56) -> -0.079519787 | P6: 1 | Q6: 1
A7: 1 | B7: 1 | P7: 1 | Q7: #DIV/0! | R7: 1
A8: 1 | B8: 1
A9: 1 | B9: 1
A10: 1 | B10: 2
A11: 1 | B11: 2
A12: 1 | B12: 2 | D12: SUMMARY OUTPUT
A13: 1 | B13: 1
A14: 1 | B14: 2 | D14: Regression Statistics
A15: 1 | B15: 1 | D15: Multiple R | E15: 0.079519787
A16: 1 | B16: 1 | D16: R Square | E16: 0.0063233966
A17: 1 | B17: 2 | D17: Adjusted R Square | E17: -0.012425219
A18: 1 | B18: 1 | D18: Standard Error | E18: 0.13567509
A19: 1 | B19: 1 | D19: Observations | E19: 55
A20: 1 | B20: 1
A21: 1 | B21: 2 | D21: ANOVA
A22: 1 | B22: 1 | E22: df | F22: SS | G22: MS | H22: F | I22: Significance F
A23: 1 | B23: 2 | D23: Regression | E23: 1 | F23: 0.0062084257 | G23: 0.0062084257 | H23: 0.33727273 | I23: 0.56386913
A24: 1 | B24: 1 | D24: Residual | E24: 53 | F24: 0.97560976 | G24: 0.018407731
A25: 1 | B25: 1 | D25: Total | E25: 54 | F25: 0.98181818
A26: 1 | B26: 1
A27: 1 | B27: 1 | E27: Coefficients | F27: Standard Error | G27: t Stat | H27: P-value | I27: Lower 95% | J27: Upper 95% | K27: Lower 95,0% | L27: Upper 95,0%
A28: 1 | B28: 1 | D28: Intercept | E28: 1.0487805 | F28: 0.055773777 | G28: 18.804186 | H28: 4.1433689e-25 | I28: 0.93691246 | J28: 1.1606485 | K28: 0.93691246 | L28: 1.1606485
A29: 1 | B29: 1 | D29: Saya pernah/sedang menggunakan software bajakan | E29: -0.024390244 | F29: 0.041997702 | G29: -0.58075186 | H29: 0.56386913 | I29: -0.10862697 | J29: 0.059846479 | K29: -0.10862697 | L29: 0.059846479
A30: 1 | B30: 1
A31: 1 | B31: 2
A32: 1 | B32: 1
A33: 1 | B33: 2
A34: 1 | B34: 2
A35: 1 | B35: 1
A36: 1 | B36: 2
A37: 1 | B37: 2
A38: 1 | B38: 1
A39: 1 | B39: 2
A40: 1 | B40: 1
...

Sheet Akses pembayaran
A1: Saya memiliki akses pembayaran international untuk pembelian lisensi software (paypall, credit card) | B1: Saya pernah/sedang menggunakan software bajakan
A2: 2 | B2: 1
A3: 2 | B3: 1
A4: 2 | B4: 1
A5: 1 | B5: 1
A6: 2 | B6: 1
A7: 2 | B7: 1
A8: 2 | B8: 1
A9: 2 | B9: 1
A10: 2 | B10: 2 | D10: SUMMARY OUTPUT
A11: 2 | B11: 2
A12: 1 | B12: 2 | D12: Regression Statistics
A13: 1 | B13: 1 | D13: Multiple R | E13: 0.037199301
A14: 2 | B14: 2 | D14: R Square | E14: 0.001383788
A15: 2 | B15: 1 | D15: Adjusted R Square | E15: -0.017458027
A16: 2 | B16: 1 | D16: Standard Error | E16: 0.47765809
A17: 2 | B17: 2 | D17: Observations | E17: 55
A18: 2 | B18: 1
A19: 1 | B19: 1 | D19: ANOVA
A20: 2 | B20: 1 | E20: df | F20: SS | G20: MS | H20: F | I20: Significance F
A21: 2 | B21: 2 | D21: Regression | E21: 1 | F21: 0.016756414 | G21: 0.016756414 | H21: 0.073442391 | I21: 0.78744175
A22: 1 | B22: 1 | D22: Residual | E22: 53 | F22: 12.092334 | G22: 0.22815725
A23: 2 | B23: 2 | D23: Total | E23: 54 | F23: 12.109091
A24: 2 | B24: 1
A25: 1 | B25: 1 | E25: Coefficients | F25: Standard Error | G25: t Stat | H25: P-value | I25: Lower 95% | J25: Upper 95% | K25: Lower 95,0% | L25: Upper 95,0%
A26: 1 | B26: 1 | D26: Intercept | E26: 1.7229965 | F26: 0.1963573 | G26: 8.7748022 | H26: 6.6109809e-12 | I26: 1.3291536 | J26: 2.1168394 | K26: 1.3291536 | L26: 2.1168394
A27: 2 | B27: 1 | D27: Saya pernah/sedang menggunakan software bajakan | E27: -0.040069686 | F27: 0.14785722 | G27: -0.27100257 | H27: 0.78744175 | I27: -0.33663372 | J27: 0.25649434 | K27: -0.33663372 | L27: 0.25649434
A28: 2 | B28: 1
A29: 2 | B29: 1
A30: 2 | B30: 1
A31: 1 | B31: 2
A32: 1 | B32: 1
A33: 1 | B33: 2
A34: 1 | B34: 2
A35: 1 | B35: 1
A36: 2 | B36: 2
A37: 1 | B37: 2
A38: 1 | B38: 1
A39: 2 | B39: 2
... A56: 1 | B56: 1

Sheet Penghasilan
A1: Penghasilan/ Uang saku perbulan | B1: Saya pernah/sedang menggunakan software bajakan
A2: 1 | B2: 1
A3: 1 | B3: 1
A4: 2 | B4: 1
A5: 1 | B5: 1
A6: 1 | B6: 1
A7: 1 | B7: 1
A8: 2 | B8: 1
A9: 1 | B9: 1
A10: 1 | B10: 2 | D10: SUMMARY OUTPUT
A11: 1 | B11: 2
A12: 2 | B12: 2 | D12: Regression Statistics
A13: 2 | B13: 1 | D13: Multiple R | E13: 0.29291546
A14: 1 | B14: 2 | D14: R Square | E14: 0.085799467
A15: 1 | B15: 1 | D15: Adjusted R Square | E15: 0.0685504
A16: 2 | B16: 1 | D16: Standard Error | E16: 0.53245839
A17: 1 | B17: 2 | D17: Observations | E17: 55
A18: 2 | B18: 1
A19: 1 | B19: 1 | D19: ANOVA
A20: 1 | B20: 1 | E20: df | F20: SS | G20: MS | H20: F | I20: Significance F
A21: 1 | B21: 2 | D21: Regression | E21: 1 | F21: 1.4102312 | G21: 1.4102312 | H21: 4.9741513 | I21: 0.029986282
A22: 2 | B22: 1 | D22: Residual | E22: 53 | F22: 15.026132 | G22: 0.28351193
A23: 1 | B23: 2 | D23: Total | E23: 54 | F23: 16.436364
A24: 1 | B24: 1
A25: 1 | B25: 1 | E25: Coefficients | F25: Standard Error | G25: t Stat | H25: P-value | I25: Lower 95% | J25: Upper 95% | K25: Lower 95,0% | L25: Upper 95,0%
A26: 1 | B26: 1 | D26: Intercept | E26: 1.8066202 | F26: 0.21888479 | G26: 8.2537493 | H26: 4.4100655e-11 | I26: 1.3675929 | J26: 2.2456475 | K26: 1.3675929 | L26: 2.2456475
A27: 1 | B27: 1 | D27: Saya pernah/sedang menggunakan software bajakan | E27: -0.36759582 | F27: 0.16482044 | G27: -2.2302805 | H27: 0.029986282 | I27: -0.69818376 | J27: -0.037007881 | K27: -0.69818376 | L27: -0.037007881
A28: 1 | B28: 1
A29: 2 | B29: 1
A30: 2 | B30: 1
A31: 1 | B31: 2
A32: 1 | B32: 1
A33: 1 | B33: 2
A34: 1 | B34: 2
A35: 1 | B35: 1
A36: 1 | B36: 2
A37: 1 | B37: 2
A38: 1 | B38: 1
A39: 1 | B39: 2
... A56: 3 | B56: 1

Sheet Gender vs dependen
A1: Gender | B1: Saya pernah/sedang menggunakan software bajakan
A2: 1 | B2: 1
A3: 1 | B3: 1
A4: 1 | B4: 1
A5: 1 | B5: 1
A6: 1 | B6: 1
A7: 1 | B7: 2
A8: 1 | B8: 1
A9: 1 | B9: 1
A10: 1 | B10: 1
A11: 1 | B11: 1
A12: 1 | B12: 1
A13: 1 | B13: 2
... A22: 1 | B22: 2
A23: 1 | B23: 1 | E23: 5 dari 32 | F23: yang gak
A24: 1 | B24: 2 | E24: 9 dari 23 | F24: yang gak
A25: 1 | B25: 1
A26: 1 | B26: 1
A27: 1 | B27: 1
A28: 1 | B28: 1
A29: 1 | B29: 1
A30: 1 | B30: 1
A31: 1 | B31: 1
A32: 1 | B32: 1
A33: 1 | B33: 1 | F33: SUMMARY OUTPUT
A34: 2 | B34: 1
A35: 2 | B35: 1 | F35: Regression Statistics
A36: 2 | B36: 1 | F36: Multiple R | G36: 0.26616519
A37: 2 | B37: 2 | F37: R Square | G37: 0.070843906
A38: 2 | B38: 2 | F38: Adjusted R Square | G38: 0.053312659
A39: 2 | B39: 2 | F39: Standard Error | G39: 0.4843552
A40: 2 | B40: 1 | F40: Observations | G40: 55
A41: 2 | B41: 2
A42: 2 | B42: 2 | F42: ANOVA
A43: 2 | B43: 1 | G43: df | H43: SS | I43: MS | J43: F | K43: Significance F
A44: 2 | B44: 1 | F44: Regression | G44: 1 | H44: 0.94802027 | I44: 0.94802027 | J44: 4.0410078 | K44: 0.049508643
A45: 2 | B45: 1 | F45: Residual | G45: 53 | H45: 12.433798 | I45: 0.23459996
A46: 2 | B46: 2 | F46: Total | G46: 54 | H46: 13.381818
A47: 2 | B47: 2
A48: 2 | B48: 2 | G48: Coefficients | H48: Standard Error | I48: t Stat | J48: P-value | K48: Lower 95% | L48: Upper 95% | M48: Lower 95,0% | N48: Upper 95,0%
...

Sheet Umur
A1: Umur | B1: Saya pernah/sedang menggunakan software bajakan
A2: 21 | B2: 1
A3: 18 | B3: 1
A4: 17 | B4: 1
A5: 18 | B5: 1
A6: 18 | B6: 1
A7: 18 | B7: 1
A8: 20 | B8: 1
A9: 18 | B9: 1
A10: 18 | B10: 2 | D10: SUMMARY OUTPUT
A11: 19 | B11: 2
A12: 18 | B12: 2 | D12: Regression Statistics
A13: 17 | B13: 1 | D13: Multiple R | E13: 0.11583258
A14: 19 | B14: 2 | D14: R Square | E14: 0.013417187
A15: 19 | B15: 1 | D15: Adjusted R Square | E15: -0.0051975833
A16: 18 | B16: 1 | D16: Standard Error | E16: 0.96123332
A17: 17 | B17: 2 | D17: Observations | E17: 55
A18: 19 | B18: 1
A19: 17 | B19: 1 | D19: ANOVA
A20: 19 | B20: 1 | E20: df | F20: SS | G20: MS | H20: F | I20: Significance F
A21: 18 | B21: 2 | D21: Regression | E21: 1 | F21: 0.66598036 | G21: 0.66598036 | H21: 0.72078176 | I21: 0.39970609
A22: 18 | B22: 1 | D22: Residual | E22: 53 | F22: 48.970383 | G22: 0.9239695
A23: 19 | B23: 2 | D23: Total | E23: 54 | F23: 49.636364
A24: 17 | B24: 1
A25: 18 | B25: 1 | E25: Coefficients | F25: Standard Error | G25: t Stat | H25: P-value | I25: Lower 95% | J25: Upper 95% | K25: Lower 95,0% | L25: Upper 95,0%
A26: 20 | B26: 1 | D26: Intercept | E26: 18.862369 | F26: 0.39514704 | G26: 47.735064 | H26: 3.1107291e-45 | I26: 18.069805 | J26: 19.654934 | K26: 18.069805 | L26: 19.654934
A27: 18 | B27: 1 | D27: Dependent | E27: -0.25261324 | F27: 0.29754607 | G27: -0.84898867 | H27: 0.39970609 | I27: -0.84941507 | J27: 0.34418859 | K27: -0.84941507 | L27: 0.34418859
A28: 19 | B28: 1
A29: 19 | B29: 1
A30: 18 | B30: 1
A31: 18 | B31: 2
A32: 19 | B32: 1
A33: 18 | B33: 2
A34: 18 | B34: 2
A35: 19 | B35: 1
A36: 17 | B36: 2
A37: 19 | B37: 2
A38: 18 | B38: 1
A39: 20 | B39: 2
... A56: 21 | B56: 1
...

Sheet Pembajakan perangkat lunak
A1: Timestamp | B1: Nama | C1: Umur | D1: Gender | E1: Penghasilan/ Uang saku perbulan | F1: Saya memiliki akses pembayaran international untuk pembelian lisensi software (paypall, credit card) | G1: Saya pernah/sedang menggunakan software bajakan | H1: Saya memiliki komputer/laptop pribadi | I1: Saya sudah menggunakan komputer/laptop pribadi sejak | J1: Pembajakan adalah tindakan yang wajar karena membantu masyarakat yang tidak mampu mendapatkan Software | K1: Pembajakan software tidak boleh dilakukan, sekalipun biayanya mahal dan saya tidak mampu membeli lisensinya | L1: Menurut saya pembajakan software dapat merugikan perusahaan | M1: Saya merasa malu dan bersalah ketika menggunakan software bajakan | N1: Saya tahu dan paham tentang hukum hak cipta | O1: Saya takut akan dijerat hukum jika menggunakan software bajakan | P1: Saya akan berhenti menggunakan software bajakan jika Hukum melarangnya
A2: 2023/09/25 10:06:24 PM GMT+7 | B2: Mahen | C2: 21 | D2: Laki-Laki | E2: Rp. 0 sampai Rp. 2.500.000,00 | F2: Tidak | G2: Ya | H2: Ya | I2: >5 tahun | J2: 5 | K2: 5 | L2: 5 | M2: 5 | N2: 5 | O2: Ya | P2: Ya
A3: 2023/09/25 10:06:34 PM GMT+7 | B3: Vanya | C3: 18 | D3: Perempuan | E3: Rp. 0 sampai Rp. 2.500.000,00 | F3: Tidak | G3: Ya | H3: Ya | I3: 1-5 tahun | J3: 2 | K3: 2 | L3: 4 | M3: 4 | N3: 4 | O3: Ya | P3: Ya
A4: 2023/09/25 10:07:33 PM GMT+7 | B4: Imtiyaz Shafhal Afif | C4: 17 | D4: Laki-Laki | E4: Rp. 2.500.001,00 sampai Rp. 5.000.000,00 | F4: Tidak | G4: Ya | H4: Ya | I4: 1-5 tahun | J4: 1 | K4: 3 | L4: 5 | M4: 3 | N4: 2 | O4: Tidak | P4: Ya
A5: 2023/09/25 10:08:06 PM GMT+7 | B5: Favian Astama | C5: 18 | D5: Laki-Laki | E5: Rp. 0 sampai Rp. 2.500.000,00 | F5: Ya | G5: Ya | H5: Ya | I5: 1-5 tahun | J5: 4 | K5: 4 | L5: 5 | M5: 3 | N5: 4 | O5: Ya | P5: Ya
A6: 2023/09/25 10:12:20 PM GMT+7 | B6: Zaki Rizal R | C6: 18 | D6: Laki-Laki | E6: Rp. 0 sampai Rp. 2.500.000,00 | F6: Tidak | G6: Ya | H6: Ya | I6: >5 tahun | J6: 3 | K6: 2 | L6: 4 | M6: 4 | N6: 3 | O6: Ya | P6: Ya
A7: 2023/09/25 10:13:50 PM GMT+7 | B7: Tsanita Shafa Hadinanda | C7: 18 | D7: Perempuan | E7: Rp. 0 sampai Rp. 2.500.000,00 | F7: Tidak | G7: Ya | H7: Ya | I7: >5 tahun | J7: 2 | K7: 4 | L7: 5 | M7: 4 | N7: 5 | O7: Ya | P7: Ya
A8: 2023/09/25 10:15:06 PM GMT+7 | B8: Ahmadhian Daffa Yudistira | C8: 20 | D8: Laki-Laki | E8: Rp. 2.500.001,00 sampai Rp. 5.000.000,00 | F8: Tidak | G8: Ya | H8: Ya | I8: >5 tahun | J8: 4 | K8: 2 | L8: 2 | M8: 1 | N8: 4 | O8: Tidak | P8: Tidak
A9: 2023/09/25 10:18:36 PM GMT+7 | B9: Bernadetta Graciela | C9: 18 | D9: Perempuan | E9: Rp. 0 sampai Rp. 2.500.000,00 | F9: Tidak | G9: Ya | H9: Ya | I9: >5 tahun | J9: 2 | K9: 4 | L9: 5 | M9: 4 | N9: 4 | O9: Ya
A10: 2023/09/25 10:20:47 PM GMT+7 | C10: 18 | D10: Perempuan | E10: Rp. 0 sampai Rp. 2.500.000,00 | F10: Tidak | G10: Tidak | H10: Ya | I10: >5 tahun | J10: 2 | K10: 4 | L10: 5 | M10: 5 | N10: 5 | O10: Ya | P10: Tidak
A11: 2023/09/25 10:21:41 PM GMT+7 | B11: Rafindra Nabiel Fawwaz | C11: 19 | D11: Laki-Laki | E11: Rp. 0 sampai Rp. 2.500.000,00 | F11: Tidak | G11: Tidak | H11: Ya | I11: >5 tahun | J11: 3 | K11: 3 | L11: 5 | M11: 4 | N11: 5 | O11: Ya
A12: 2023/09/25 10:22:20 PM GMT+7 | B12: Devika Rahman | C12: 18 | D12: Perempuan | E12: Rp. 2.500.001,00 sampai Rp. 5.000.000,00 | F12: Ya | G12: Tidak | H12: Ya | I12: >5 tahun | J12: 1 | K12: 5 | L12: 5 | M12: 4 | N12: 4 | O12: Ya | P12: Ya
A13: 2023/09/25 10:24:57 PM GMT+7 | B13: Ananda Donelly Reksana | C13: 17 | D13: Laki-Laki | E13: Rp. 2.500.001,00 sampai Rp. 5.000.000,00 | F13: Ya | G13: Ya | H13: Ya | I13: >5 tahun | J13: 2 | K13: 4 | L13: 5 | M13: 4 | N13: 4 | O13: Ya | P13: Ya
A14: 2023/09/25 10:25:56 PM GMT+7 | B14: Fadhila Kamila | C14: 19 | D14: Perempuan | E14: Rp. 0 sampai Rp. 2.500.000,00 | F14: Tidak | G14: Tidak | H14: Ya | I14: >5 tahun | J14: 3 | K14: 4 | L14: 4 | M14: 4 | N14: 3 | O14: Tidak | P14: Ya
A15: 2023/09/25 10:37:09 PM GMT+7 | B15: Lita Sari Banjarnahor | C15: 19 | D15: Perempuan | E15: Rp. 0 sampai Rp. 2.500.000,00 | F15: Tidak | G15: Ya | H15: Ya | I15: 1-5 tahun | J15: 2 | K15: 1 | L15: 5 | M15: 5 | N15: 3 | O15: Ya | P15: Ya
A16: 2023/09/25 10:37:15 PM GMT+7 | B16: Fernandio Farrel Putra Susilo | C16: 18 | D16: Laki-Laki | E16: Rp. 2.500.001,00 sampai Rp. 5.000.000,00 | F16: Tidak | G16: Ya | H16: Ya | I16: >5 tahun | J16: 3 | K16: 2 | L16: 4 | M16: 2 | N16: 3 | O16: Tidak | P16: Ya
A17: 2023/09/25 10:37:29 PM GMT+7 | B17: Ayesha Hana Azkiya | C17: 17 | D17: Perempuan | E17: Rp. 0 sampai Rp. 2.500.000,00 | F17: Tidak | G17: Tidak | H17: Ya | I17: 1-5 tahun | J17: 2 | K17: 4 | L17: 5 | M17: 5 | N17: 3 | O17: Ya | P17: Ya
A18: 2023/09/25 10:41:18 PM GMT+7 | B18: Muhammad Rafi Widya Danendra | C18: 19 | D18: Laki-Laki | E18: Rp. 2.500.001,00 sampai Rp. 5.000.000,00 | F18: Tidak | G18: Ya | H18: Ya | I18: >5 tahun | J18: 2 | K18: 4 | L18: 5 | M18: 2 | N18: 4 | O18: Tidak | P18: Tidak
A19: 2023/09/25 10:51:21 PM GMT+7 | B19: Umar Al Haddad | C19: 17 | D19: Laki-Laki | E19: Rp. 0 sampai Rp. 2.500.000,00 | F19: Ya | G19: Ya | H19: Ya | I19: >5 tahun | J19: 3 | K19: 3 | L19: 3 | M19: 3 | N19: 3 | O19: Ya | P19: Ya
A20: 2023/09/25 11:15:23 PM GMT+7 | B20: Gery | C20: 19 | D20: Laki-Laki | E20: Rp. 0 sampai Rp. 2.500.000,00 | F20: Tidak | G20: Ya | H20: Ya | I20: >5 tahun | J20: 3 | K20: 5 | L20: 5 | M20: 4 | N20: 4 | O20: Ya | P20: Ya
A21: 2023/09/25 11:49:05 PM GMT+7 | B21: Felix Prajna Santoso | C21: 18 | D21: Laki-Laki | E21: Rp. 0 sampai Rp. 2.500.000,00 | F21: Tidak | G21: Tidak | H21: Ya | I21: <1 tahun | J21: 2 | K21: 5 | L21: 5 | M21: 5 | N21: 5 | O21: Ya | P21: Ya
A22: 2023/09/26 12:17:28 AM GMT+7 | B22: Arya Wiraguna Dwiputra | C22: 18 | D22: Laki-Laki | E22: Rp. 2.500.001,00 sampai Rp. 5.000.000,00 | F22: Ya | G22: Ya | H22: Ya | I22: >5 tahun | J22: 4 | K22: 3 | L22: 4 | M22: 3 | N22: 3 | O22: Ya | P22: Tidak
A23: 2023/09/26 3:33:43 AM GMT+7 | B23: Astrid Meilendra | C23: 19 | D23: Perempuan | E23: Rp. 0 sampai Rp. 2.500.000,00 | F23: Tidak | G23: Tidak | H23: Ya | I23: 1-5 tahun | J23: 2 | K23: 3 | L23: 3 | M23: 3 | N23: 3 | O23: Ya | P23: Ya
... A25: 2023/09/26 5:05:53 AM GMT+7 | B25: Alexander Allan | C25: 18 | D25: Laki-Laki | E25: Rp. 0 sampai Rp. 2.500.000,00 | F25: Ya | G25: Ya | H25: Ya | I25: 1-5 tahun | J25: 4 | K25: 3 | L25: 5 | M25: 1 | N25: 3 | O25: Tidak | P25: Tidak
A26: 2023/09/26 5:21:58 AM GMT+7 | B26: Zulfan | C26: 20 | D26: Laki-Laki | E26: Rp. 0 sampai Rp. 2.500.000,00 | F26: Ya | G26: Ya | H26: Ya | I26: 1-5 tahun | J26: 2 | K26: 4 | L26: 5 | M26: 5 | N26: 5 | O26: Tidak
A27: 2023/09/26 6:50:21 AM GMT+7 | B27: I Putu Febryan Khrisyantara | C27: 18 | D27: Laki-Laki | E27: Rp. 0 sampai Rp. 2.500.000,00 | F27: Tidak | G27: Ya | H27: Ya | I27: >5 tahun | J27: 3 | K27: 4 | L27: 5 | M27: 5 | N27: 5 | O27: Ya | P27: Ya
A28: 2023/09/26 6:53:23 AM GMT+7 | C28: 19 | D28: Perempuan | E28: Rp. 0 sampai Rp. 2.500.000,00 | F28: Tidak | G28: Ya | H28: Ya | I28: >5 tahun | J28: 4 | K28: 2 | L28: 3 | M28: 1 | N28: 4 | O28: Tidak | P28: Tidak
A29: 2023/09/26 6:53:36 AM GMT+7 | B29: - | C29: 19 | D29: Perempuan | E29: Rp. 2.500.001,00 sampai Rp. 5.000.000,00 | F29: Tidak | G29: Ya | H29: Ya | I29: <1 tahun | J29: 2 | K29: 5 | L29: 5 | M29: 4 | N29: 3 | O29: Ya | P29: Tidak
A30: 2023/09/26 7:07:49 AM GMT+7 | B30: Muhamad Arif Satriyo | C30: 18 | D30: Laki-Laki | E30: Rp. 2.500.001,00 sampai Rp. 5.000.000,00 | F30: Tidak | G30: Ya | H30: Ya | I30: 1-5 tahun | J30: 5 | K30: 2 | L30: 5 | M30: 2 | N30: 3 | O30: Ya | P30: Ya
A31: 2023/09/26 7:08:37 AM GMT+7 | B31: Javier | C31: 18 | D31: Laki-Laki | E31: Rp. 0 sampai Rp. 2.500.000,00 | F31: Ya | G31: Tidak | H31: Ya | I31: <1 tahun | J31: 3 | K31: 3 | L31: 3 | M31: 4 | N31: 4 | O31: Tidak | P31: Tidak
A32: 2023/09/26 7:08:38 AM GMT+7 | B32: Akhtar Zia Faizarrobbi | C32: 19 | D32: Laki-Laki | E32: Rp. 0 sampai Rp. 2.500.000,00 | F32: Ya | G32: Ya | H32: Ya | I32: >5 tahun | J32: 3 | K32: 5 | L32: 5 | M32: 2 | N32: 4 | O32: Tidak | P32: Tidak
A33: 2023/09/26 7:08:51 AM GMT+7 | B33: Arsya Nueva Delavera | C33: 18 | D33: Perempuan | E33: Rp. 0 sampai Rp. 2.500.000,00 | F33: Ya | G33: Tidak | H33: Ya | I33: >5 tahun | J33: 1 | K33: 5 | L33: 5 | M33: 5 | N33: 4 | O33: Ya | P33: Ya
A34: 2023/09/26 7:09:42 AM GMT+7 | B34: Diva Nesia Putri | C34: 18 | D34: Perempuan | E34: Rp. 0 sampai Rp. 2.500.000,00 | F34: Ya | G34: Tidak | H34: Ya | I34: >5 tahun | J34: 1 | K34: 5 | L34: 5 | M34: 5 | N34: 4 | O34: Ya | P34: Ya
A35: 2023/09/26 7:10:25 AM GMT+7 | B35: Dzaky Ahmad | C35: 19 | D35: Laki-Laki | E35: Rp. 0 sampai Rp. 2.500.000,00 | F35: Ya | G35: Ya | H35: Ya | I35: 1-5 tahun | J35: 2 | K35: 2 | L35: 2 | M35: 2 | N35: 2 | O35: Ya | P35: Tidak
A36: 2023/09/26 7:10:56 AM GMT+7 | B36: Danovanz | C36: 17 | D36: Laki-Laki | E36: Rp. 0 sampai Rp. 2.500.000,00 | F36: Tidak | G36: Tidak | H36: Ya | I36: >5 tahun | J36: 4 | K36: 4 | L36: 4 | M36: 4 | N36: 4 | O36: Ya | P36: Tidak
A37: 2023/09/26 7:15:06 AM GMT+7 | B37: Tiara Aulia Azadirachta Indica | C37: 19 | D37: Perempuan | E37: Rp. 0 sampai Rp. 2.500.000,00 | F37: Ya | G37: Tidak | H37: Ya | I37: <1 tahun | J37: 4 | K37: 3 | L37: 4 | M37: 3 | N37: 2 | O37: Ya | P37: Ya
A38: 2023/09/26 7:29:26 AM GMT+7 | B38: Satria Pinandita | C38: 18 | D38: Laki-Laki | E38: Rp. 0 sampai Rp. 2.500.000,00 | F38: Ya | G38: Ya | H38: Ya | I38: >5 tahun | J38: 5 | K38: 1 | L38: 4 | M38: 1 | N38: 4 | O38: Tidak | P38: Ya
A39: 2023/09/26 8:07:47 AM GMT+7 | B39: Rayhan Fahmi | C39: 20 | D39: Laki-Laki | E39: Rp. 0 sampai Rp. 2.500.000,00 | F39: Tidak | G39: Tidak | H39: Ya | I39: >5 tahun | J39: 1 | K39: 4 | L39: 4 | M39: 2 | N39: 2 | O39: Ya | P39: Tidak
A40: 2023/09/26 9:12:07 AM GMT+7 | B40: Arjuna Putra | C40: 19 | D40: Laki-Laki | E40: Rp. 0 sampai Rp. 2.500.000,00 | F40: Tidak | G40: Ya | H40: Ya | I40: >5 tahun | J40: 3 | K40: 2 | L40: 5 | M40: 2 | N40: 4 | O40: Tidak | P40: Tidak
... A50: 2023/09/26 4:30:52 PM GMT+7 | B50: Anas Ghifari | C50: 19 | D50: Laki-Laki | E50: Rp. 2.500.001,00 sampai Rp. 5.000.000,00 | F50: Tidak | G50: Ya | H50: Ya | I50: >5 tahun | J50: 3 | K50: 3 | L50: 4 | M50: 2 | N50: 3 | O50: Ya | P50: Ya
...
